Workbook

Sheet Consolidado de precios
C1: Tamaño del proyecto 2D (km) - Tiempo | D1: 830 | AE1: TRUE
C2: Tamaño del proyecto 2D (km) - Profundidad | D2: 125
C3: Tamaño del proyecto 3D (km²) - Tiempo | D3: 0 | AE3: FALSE
C4: Tamaño del proyecto 3D (km²) - Profundidad | D4: 0
C5: Número de tomografías 2D | D5: 6
C6: Número de tomografías 3D | D6: 0
G7: Absolute | H7: AGT | I7: EGS | J7: GT | K7: Geotomo | L7: Inforpetrol | M7: Petroseis | N7: Schlumberger | O7: Tecc | P7: Z-Terra | R7: Absolute | S7: AGT | T7: EGS | U7: GT | V7: Geotomo | W7: Inforpetrol | X7: Petroseis | Y7: Schlumberger | Z7: Tecc | AA7: Z-Terra
B8: UNIDAD | C8: DESCRIPCION AMPLIADA DEL SERVICIO | D8: Project Size | F8: Aplica | G8: VR UNIT USD $ | H8: VR UNIT USD $ | I8: VR UNIT USD $ | J8: VR UNIT USD $ | K8: VR UNIT USD $ | L8: VR UNIT USD $ | M8: VR UNIT USD $ | N8: VR UNIT USD $ | O8: VR UNIT USD $ | P8: VR UNIT USD $ | Q8: Aplica 2 | R8: Costo por servicio | S8: Costo por servicio | T8: Costo por servicio | U8: Costo por servicio | V8: Costo por servicio | W8: Costo por servicio | X8: Costo por servicio | Y8: Costo por servicio | Z8: Costo por servicio | AA8: Costo por servicio
B9: km 2D | C9: 2D Up-front processing (include Data Audit) | D9: <200 km | F9: FALSE | G9: 50 | H9: 47.5 | I9: 65 | J9: 28 | K9: 67.43 | L9: 20 | M9: 7.5 | N9: 119.12 | O9: 60 | P9: 30 | Q9: =AND($D$1>0,$D$1<200,F9=TRUE) -> FALSE | R9: =IF($Q9=TRUE,G9*$D$1,0) -> 0 | S9: =IF($Q9=TRUE,H9*$D$1,0) -> 0 | T9: =IF($Q9=TRUE,I9*$D$1,0) -> 0 | U9: =IF($Q9=TRUE,J9*$D$1,0) -> 0 | V9: =IF($Q9=TRUE,K9*$D$1,0) -> 0 | W9: =IF($Q9=TRUE,L9*$D$1,0) -> 0 | X9: =IF($Q9=TRUE,M9*$D$1,0) -> 0 | Y9: =IF($Q9=TRUE,N9*$D$1,0) -> 0 | ... AA9: =IF($Q9=TRUE,P9*$D$1,0) -> 0
B10: km 2D | C10: 2D Up-front processing (include Data Audit) | D10: 200-600 km | F10: FALSE | G10: 50 | H10: 45 | I10: 60 | J10: 28 | K10: 67.43 | L10: 18 | M10: 7 | N10: 119.12 | O10: 57 | P10: 28 | Q10: =AND($D$1>=200,$D$1<600,F10=TRUE) -> FALSE | R10: =IF($Q10=TRUE,G10*$D$1,0) -> 0 | S10: =IF($Q10=TRUE,H10*$D$1,0) -> 0 | T10: =IF($Q10=TRUE,I10*$D$1,0) -> 0 | U10: =IF($Q10=TRUE,J10*$D$1,0) -> 0 | V10: =IF($Q10=TRUE,K10*$D$1,0) -> 0 | W10: =IF($Q10=TRUE,L10*$D$1,0) -> 0 | X10: =IF($Q10=TRUE,M10*$D$1,0) -> 0 | Y10: =IF($Q10=TRUE,N10*$D$1,0) -> 0 | ... AA10: =IF($Q10=TRUE,P10*$D$1,0) -> 0
B11: km 2D | C11: 2D Up-front processing (include Data Audit) | D11: >600 km | F11: TRUE | G11: 50 | H11: 42.75 | I11: 50 | J11: 28 | K11: 67.43 | L11: 16 | M11: 6 | N11: 119.12 | O11: 54 | P11: 25 | Q11: =AND($D$1>=600,F11=TRUE) -> TRUE | R11: =IF($Q11=TRUE,G11*$D$1,0) -> 41500 | S11: =IF($Q11=TRUE,H11*$D$1,0) -> 35482.5 | T11: =IF($Q11=TRUE,I11*$D$1,0) -> 41500 | U11: =IF($Q11=TRUE,J11*$D$1,0) -> 23240 | V11: =IF($Q11=TRUE,K11*$D$1,0) -> 55966.9 | W11: =IF($Q11=TRUE,L11*$D$1,0) -> 13280 | X11: =IF($Q11=TRUE,M11*$D$1,0) -> 4980 | Y11: =IF($Q11=TRUE,N11*$D$1,0) -> 98869.6 | ... AA11: =IF($Q11=TRUE,P11*$D$1,0) -> 20750
B12: km² 3D | C12: 3D Up-front processing (include Data Audit) | D12: 0-200 km² | F12: FALSE | G12: 90 | H12: 80 | I12: 90 | J12: 63 | K12: 54 | L12: 30 | M12: 16 | N12: 173.26 | O12: 60 | P12: 50 | Q12: =AND($D$3>0,$D$3<200,F12=TRUE) -> FALSE | R12: =IF($Q12=TRUE,G12*$D$3,0) -> 0 | S12: =IF($Q12=TRUE,H12*$D$3,0) -> 0 | T12: =IF($Q12=TRUE,I12*$D$3,0) -> 0 | U12: =IF($Q12=TRUE,J12*$D$3,0) -> 0 | V12: =IF($Q12=TRUE,K12*$D$3,0) -> 0 | W12: =IF($Q12=TRUE,L12*$D$3,0) -> 0 | X12: =IF($Q12=TRUE,M12*$D$3,0) -> 0 | Y12: =IF($Q12=TRUE,N12*$D$3,0) -> 0 | ... AA12: =IF($Q12=TRUE,P12*$D$3,0) -> 0
B13: km² 3D | C13: 3D Up-front processing (include Data Audit) | D13: 200-500 km² | F13: FALSE | G13: 75 | H13: 76.5 | I13: 80 | J13: 63 | K13: 54 | L13: 30 | M13: 14.5 | N13: 173.26 | O13: 57 | P13: 47 | Q13: =AND($D$3>=200,$D$3<500,F13=TRUE) -> FALSE | R13: =IF($Q13=TRUE,G13*$D$3,0) -> 0 | S13: =IF($Q13=TRUE,H13*$D$3,0) -> 0 | T13: =IF($Q13=TRUE,I13*$D$3,0) -> 0 | U13: =IF($Q13=TRUE,J13*$D$3,0) -> 0 | V13: =IF($Q13=TRUE,K13*$D$3,0) -> 0 | W13: =IF($Q13=TRUE,L13*$D$3,0) -> 0 | X13: =IF($Q13=TRUE,M13*$D$3,0) -> 0 | Y13: =IF($Q13=TRUE,N13*$D$3,0) -> 0 | ... AA13: =IF($Q13=TRUE,P13*$D$3,0) -> 0
B14: km² 3D | C14: 3D Up-front processing (include Data Audit) | D14: >500 km² | F14: FALSE | G14: 75 | H14: 72.5 | I14: 70 | J14: 63 | K14: 49 | L14: 25 | M14: 12.5 | N14: 173.26 | O14: 54 | P14: 45 | Q14: =AND($D$3>=500,F14=TRUE) -> FALSE | R14: =IF($Q14=TRUE,G14*$D$3,0) -> 0 | S14: =IF($Q14=TRUE,H14*$D$3,0) -> 0 | T14: =IF($Q14=TRUE,I14*$D$3,0) -> 0 | U14: =IF($Q14=TRUE,J14*$D$3,0) -> 0 | V14: =IF($Q14=TRUE,K14*$D$3,0) -> 0 | W14: =IF($Q14=TRUE,L14*$D$3,0) -> 0 | X14: =IF($Q14=TRUE,M14*$D$3,0) -> 0 | Y14: =IF($Q14=TRUE,N14*$D$3,0) -> 0 | ... AA14: =IF($Q14=TRUE,P14*$D$3,0) -> 0
B15: km 2D | C15: 2D Time domain preprocessing | D15: <200 km | F15: FALSE | G15: 100 | H15: 115 | I15: 70 | J15: 119 | K15: 118 | L15: 40 | M15: 43 | N15: 435.76 | O15: 125 | P15: 65 | Q15: =AND($D$1>0,$D$1<200,F15=TRUE) -> FALSE | R15: =IF($Q15=TRUE,G15*$D$1,0) -> 0 | S15: =IF($Q15=TRUE,H15*$D$1,0) -> 0 | T15: =IF($Q15=TRUE,I15*$D$1,0) -> 0 | U15: =IF($Q15=TRUE,J15*$D$1,0) -> 0 | V15: =IF($Q15=TRUE,K15*$D$1,0) -> 0 | W15: =IF($Q15=TRUE,L15*$D$1,0) -> 0 | X15: =IF($Q15=TRUE,M15*$D$1,0) -> 0 | Y15: =IF($Q15=TRUE,N15*$D$1,0) -> 0 | ... AA15: =IF($Q15=TRUE,P15*$D$1,0) -> 0
B16: km 2D | C16: 2D Time domain preprocessing | D16: 200-600 km | F16: FALSE | G16: 100 | H16: 105 | I16: 60 | J16: 104 | K16: 98.33 | L16: 38 | M16: 40 | N16: 244.24 | O16: 118 | P16: 62 | Q16: =AND($D$1>=200,$D$1<600,F16=TRUE) -> FALSE | R16: =IF($Q16=TRUE,G16*$D$1,0) -> 0 | S16: =IF($Q16=TRUE,H16*$D$1,0) -> 0 | T16: =IF($Q16=TRUE,I16*$D$1,0) -> 0 | U16: =IF($Q16=TRUE,J16*$D$1,0) -> 0 | V16: =IF($Q16=TRUE,K16*$D$1,0) -> 0 | W16: =IF($Q16=TRUE,L16*$D$1,0) -> 0 | X16: =IF($Q16=TRUE,M16*$D$1,0) -> 0 | Y16: =IF($Q16=TRUE,N16*$D$1,0) -> 0 | ... AA16: =IF($Q16=TRUE,P16*$D$1,0) -> 0
B17: km 2D | C17: 2D Time domain preprocessing | D17: >600 km | F17: TRUE | G17: 100 | H17: 100 | I17: 50 | J17: 100 | K17: 98.33 | L17: 35 | M17: 36 | N17: 169.13 | O17: 110 | P17: 60 | Q17: =AND($D$1>=600,F17=TRUE) -> TRUE | R17: =IF($Q17=TRUE,G17*$D$1,0) -> 83000 | S17: =IF($Q17=TRUE,H17*$D$1,0) -> 83000 | T17: =IF($Q17=TRUE,I17*$D$1,0) -> 41500 | U17: =IF($Q17=TRUE,J17*$D$1,0) -> 83000 | V17: =IF($Q17=TRUE,K17*$D$1,0) -> 81613.9 | W17: =IF($Q17=TRUE,L17*$D$1,0) -> 29050 | X17: =IF($Q17=TRUE,M17*$D$1,0) -> 29880 | Y17: =IF($Q17=TRUE,N17*$D$1,0) -> 140377.9 | ... AA17: =IF($Q17=TRUE,P17*$D$1,0) -> 49800
B18: km² 3D | C18: 3D Time domain preprocessing | D18: 0-200 km² | F18: FALSE | G18: 200 | H18: 200 | I18: 100 | J18: 216 | K18: 153 | L18: 50 | M18: 88.5 | N18: 490.88 | O18: 125 | P18: 75 | Q18: =AND($D$3>0,$D$3<200,F18=TRUE) -> FALSE | R18: =IF($Q18=TRUE,G18*$D$3,0) -> 0 | S18: =IF($Q18=TRUE,H18*$D$3,0) -> 0 | T18: =IF($Q18=TRUE,I18*$D$3,0) -> 0 | U18: =IF($Q18=TRUE,J18*$D$3,0) -> 0 | V18: =IF($Q18=TRUE,K18*$D$3,0) -> 0 | W18: =IF($Q18=TRUE,L18*$D$3,0) -> 0 | X18: =IF($Q18=TRUE,M18*$D$3,0) -> 0 | Y18: =IF($Q18=TRUE,N18*$D$3,0) -> 0 | ... AA18: =IF($Q18=TRUE,P18*$D$3,0) -> 0
B19: km² 3D | C19: 3D Time domain preprocessing | D19: 200-500 km² | F19: FALSE | G19: 150 | H19: 180 | I19: 90 | J19: 204 | K19: 153 | L19: 45 | M19: 82 | N19: 368.16 | O19: 118 | P19: 72 | Q19: =AND($D$3>=200,$D$3<500,F19=TRUE) -> FALSE | R19: =IF($Q19=TRUE,G19*$D$3,0) -> 0 | S19: =IF($Q19=TRUE,H19*$D$3,0) -> 0 | T19: =IF($Q19=TRUE,I19*$D$3,0) -> 0 | U19: =IF($Q19=TRUE,J19*$D$3,0) -> 0 | V19: =IF($Q19=TRUE,K19*$D$3,0) -> 0 | W19: =IF($Q19=TRUE,L19*$D$3,0) -> 0 | X19: =IF($Q19=TRUE,M19*$D$3,0) -> 0 | Y19: =IF($Q19=TRUE,N19*$D$3,0) -> 0 | ... AA19: =IF($Q19=TRUE,P19*$D$3,0) -> 0
B20: km² 3D | C20: 3D Time domain preprocessing | D20: >500 km² | F20: FALSE | G20: 100 | H20: 170 | I20: 80 | J20: 185 | K20: 128 | L20: 40 | M20: 74.5 | N20: 253.5 | O20: 110 | P20: 70 | Q20: =AND($D$3>=500,F20=TRUE) -> FALSE | R20: =IF($Q20=TRUE,G20*$D$3,0) -> 0 | S20: =IF($Q20=TRUE,H20*$D$3,0) -> 0 | T20: =IF($Q20=TRUE,I20*$D$3,0) -> 0 | U20: =IF($Q20=TRUE,J20*$D$3,0) -> 0 | V20: =IF($Q20=TRUE,K20*$D$3,0) -> 0 | W20: =IF($Q20=TRUE,L20*$D$3,0) -> 0 | X20: =IF($Q20=TRUE,M20*$D$3,0) -> 0 | Y20: =IF($Q20=TRUE,N20*$D$3,0) -> 0 | ... AA20: =IF($Q20=TRUE,P20*$D$3,0) -> 0
B21: km 2D | C21: 2D Pre-stack Time Migration (PreSTM) | D21: <200 km | F21: FALSE | G21: 50 | H21: 59 | I21: 75 | J21: 91 | K21: 54 | L21: 40 | M21: 27 | N21: 34.25 | O21: 105 | P21: 45 | Q21: =AND($D$1>0,$D$1<200,F21=TRUE) -> FALSE | R21: =IF($Q21=TRUE,G21*$D$1,0) -> 0 | S21: =IF($Q21=TRUE,H21*$D$1,0) -> 0 | T21: =IF($Q21=TRUE,I21*$D$1,0) -> 0 | U21: =IF($Q21=TRUE,J21*$D$1,0) -> 0 | V21: =IF($Q21=TRUE,K21*$D$1,0) -> 0 | W21: =IF($Q21=TRUE,L21*$D$1,0) -> 0 | X21: =IF($Q21=TRUE,M21*$D$1,0) -> 0 | Y21: =IF($Q21=TRUE,N21*$D$1,0) -> 0 | ... AA21: =IF($Q21=TRUE,P21*$D$1,0) -> 0
B22: km 2D | C22: 2D Pre-stack Time Migration (PreSTM) | D22: 200-600 km | F22: FALSE | G22: 50 | H22: 55 | I22: 70 | J22: 85 | K22: 54 | L22: 34 | M22: 23 | N22: 34.25 | O22: 100 | P22: 42 | Q22: =AND($D$1>=200,$D$1<600,F22=TRUE) -> FALSE | R22: =IF($Q22=TRUE,G22*$D$1,0) -> 0 | S22: =IF($Q22=TRUE,H22*$D$1,0) -> 0 | T22: =IF($Q22=TRUE,I22*$D$1,0) -> 0 | U22: =IF($Q22=TRUE,J22*$D$1,0) -> 0 | V22: =IF($Q22=TRUE,K22*$D$1,0) -> 0 | W22: =IF($Q22=TRUE,L22*$D$1,0) -> 0 | X22: =IF($Q22=TRUE,M22*$D$1,0) -> 0 | Y22: =IF($Q22=TRUE,N22*$D$1,0) -> 0 | ... AA22: =IF($Q22=TRUE,P22*$D$1,0) -> 0
B23: km 2D | C23: 2D Pre-stack Time Migration (PreSTM) | D23: >600 km | F23: TRUE | G23: 50 | H23: 53 | I23: 65 | J23: 80 | K23: 54 | L23: 29 | M23: 21 | N23: 34.25 | O23: 95 | P23: 40 | Q23: =AND($D$1>=600,F23=TRUE) -> TRUE | R23: =IF($Q23=TRUE,G23*$D$1,0) -> 41500 | S23: =IF($Q23=TRUE,H23*$D$1,0) -> 43990 | T23: =IF($Q23=TRUE,I23*$D$1,0) -> 53950 | U23: =IF($Q23=TRUE,J23*$D$1,0) -> 66400 | V23: =IF($Q23=TRUE,K23*$D$1,0) -> 44820 | W23: =IF($Q23=TRUE,L23*$D$1,0) -> 24070 | X23: =IF($Q23=TRUE,M23*$D$1,0) -> 17430 | Y23: =IF($Q23=TRUE,N23*$D$1,0) -> 28427.5 | ... AA23: =IF($Q23=TRUE,P23*$D$1,0) -> 33200
B24: km² 3D | C24: 3D Pre-stack Time Migration (PreSTM) | D24: 0-200 km² | F24: FALSE | G24: 100 | H24: 70 | I24: 60 | J24: 119 | K24: 98.33 | L24: 40 | M24: 60 | N24: 68.49 | O24: 105 | P24: 72 | Q24: =AND($D$3>0,$D$3<200,F24=TRUE) -> FALSE | R24: =IF($Q24=TRUE,G24*$D$3,0) -> 0 | S24: =IF($Q24=TRUE,H24*$D$3,0) -> 0 | T24: =IF($Q24=TRUE,I24*$D$3,0) -> 0 | U24: =IF($Q24=TRUE,J24*$D$3,0) -> 0 | V24: =IF($Q24=TRUE,K24*$D$3,0) -> 0 | W24: =IF($Q24=TRUE,L24*$D$3,0) -> 0 | X24: =IF($Q24=TRUE,M24*$D$3,0) -> 0 | Y24: =IF($Q24=TRUE,N24*$D$3,0) -> 0 | ... AA24: =IF($Q24=TRUE,P24*$D$3,0) -> 0
B25: km² 3D | C25: 3D Pre-stack Time Migration (PreSTM) | D25: 200-500 km² | F25: FALSE | G25: 90 | H25: 65 | I25: 54 | J25: 110 | K25: 97.98 | L25: 35 | M25: 55 | N25: 68.49 | O25: 100 | P25: 70 | Q25: =AND($D$3>=200,$D$3<500,F25=TRUE) -> FALSE | R25: =IF($Q25=TRUE,G25*$D$3,0) -> 0 | S25: =IF($Q25=TRUE,H25*$D$3,0) -> 0 | T25: =IF($Q25=TRUE,I25*$D$3,0) -> 0 | U25: =IF($Q25=TRUE,J25*$D$3,0) -> 0 | V25: =IF($Q25=TRUE,K25*$D$3,0) -> 0 | W25: =IF($Q25=TRUE,L25*$D$3,0) -> 0 | X25: =IF($Q25=TRUE,M25*$D$3,0) -> 0 | Y25: =IF($Q25=TRUE,N25*$D$3,0) -> 0 | ... AA25: =IF($Q25=TRUE,P25*$D$3,0) -> 0
B26: km² 3D | C26: 3D Pre-stack Time Migration (PreSTM) | D26: >500 km² | F26: FALSE | G26: 90 | H26: 60 | I26: 48 | J26: 100 | K26: 88.04 | L26: 30 | M26: 52 | N26: 68.49 | O26: 95 | P26: 67 | Q26: =AND($D$3>=500,F26=TRUE) -> FALSE | R26: =IF($Q26=TRUE,G26*$D$3,0) -> 0 | S26: =IF($Q26=TRUE,H26*$D$3,0) -> 0 | T26: =IF($Q26=TRUE,I26*$D$3,0) -> 0 | U26: =IF($Q26=TRUE,J26*$D$3,0) -> 0 | V26: =IF($Q26=TRUE,K26*$D$3,0) -> 0 | W26: =IF($Q26=TRUE,L26*$D$3,0) -> 0 | X26: =IF($Q26=TRUE,M26*$D$3,0) -> 0 | Y26: =IF($Q26=TRUE,N26*$D$3,0) -> 0 | ... AA26: =IF($Q26=TRUE,P26*$D$3,0) -> 0
B27: km 2D | C27: 2D Tomography iteration (incl. Tomo PreSDM), UP TO 5 ITERATIONS | D27: <200 km | F27: TRUE | G27: 200 | H27: 104 | I27: 185 | J27: 125 | K27: 175 | L27: 40 | M27: 39 | N27: 221.39 | O27: 305 | P27: 147 | Q27: =AND($D$2>0,$D$2<200,F27=TRUE) -> TRUE | R27: =IF($Q27=TRUE,G27*$D$2,0) -> 25000 | S27: =IF($Q27=TRUE,H27*$D$2,0) -> 13000 | T27: =IF($Q27=TRUE,I27*$D$2,0) -> 23125 | U27: =IF($Q27=TRUE,J27*$D$2,0) -> 15625 | V27: =IF($Q27=TRUE,K27*$D$2,0) -> 21875 | W27: =IF($Q27=TRUE,L27*$D$2,0) -> 5000 | X27: =IF($Q27=TRUE,M27*$D$2,0) -> 4875 | Y27: =IF($Q27=TRUE,N27*$D$2,0) -> 27673.75 | ... AA27: =IF($Q27=TRUE,P27*$D$2,0) -> 18375
B28: km 2D | C28: 2D Tomography iteration (incl. Tomo PreSDM), UP TO 5 ITERATIONS | D28: 200-600 km | F28: FALSE | G28: 200 | H28: 99 | I28: 180 | J28: 119 | K28: 170 | L28: 40 | M28: 35 | N28: 221.39 | O28: 290 | P28: 150 | Q28: =AND($D$2>=200,$D$2<600,F28=TRUE) -> FALSE | R28: =IF($Q28=TRUE,G28*$D$2,0) -> 0 | S28: =IF($Q28=TRUE,H28*$D$2,0) -> 0 | T28: =IF($Q28=TRUE,I28*$D$2,0) -> 0 | U28: =IF($Q28=TRUE,J28*$D$2,0) -> 0 | V28: =IF($Q28=TRUE,K28*$D$2,0) -> 0 | W28: =IF($Q28=TRUE,L28*$D$2,0) -> 0 | X28: =IF($Q28=TRUE,M28*$D$2,0) -> 0 | Y28: =IF($Q28=TRUE,N28*$D$2,0) -> 0 | ... AA28: =IF($Q28=TRUE,P28*$D$2,0) -> 0
B29: km 2D | C29: 2D Tomography iteration (incl. Tomo PreSDM), UP TO 5 ITERATIONS | D29: >600 km | F29: FALSE | G29: 200 | H29: 94 | I29: 170 | J29: 113 | K29: 165 | L29: 35 | M29: 32 | N29: 221.39 | O29: 280 | P29: 157 | Q29: =AND($D$2>=600,F29=TRUE) -> FALSE | R29: =IF($Q29=TRUE,G29*$D$2,0) -> 0 | S29: =IF($Q29=TRUE,H29*$D$2,0) -> 0 | T29: =IF($Q29=TRUE,I29*$D$2,0) -> 0 | U29: =IF($Q29=TRUE,J29*$D$2,0) -> 0 | V29: =IF($Q29=TRUE,K29*$D$2,0) -> 0 | W29: =IF($Q29=TRUE,L29*$D$2,0) -> 0 | X29: =IF($Q29=TRUE,M29*$D$2,0) -> 0 | Y29: =IF($Q29=TRUE,N29*$D$2,0) -> 0 | ... AA29: =IF($Q29=TRUE,P29*$D$2,0) -> 0
B30: km² 3D | C30: 3D Tomography iteration (incl. Tomo PreSDM), UP TO 5 ITERATIONS | D30: 0-200 km² | F30: FALSE | G30: 275 | H30: 260 | I30: 250 | J30: 275 | K30: 198 | L30: 50 | M30: 102 | N30: 306.54 | O30: 305 | P30: 285 | Q30: =AND($D$4>0,$D$4<200,F30=TRUE) -> FALSE | R30: =IF($Q30=TRUE,G30*$D$4,0) -> 0 | S30: =IF($Q30=TRUE,H30*$D$4,0) -> 0 | T30: =IF($Q30=TRUE,I30*$D$4,0) -> 0 | U30: =IF($Q30=TRUE,J30*$D$4,0) -> 0 | V30: =IF($Q30=TRUE,K30*$D$4,0) -> 0 | W30: =IF($Q30=TRUE,L30*$D$4,0) -> 0 | X30: =IF($Q30=TRUE,M30*$D$4,0) -> 0 | Y30: =IF($Q30=TRUE,N30*$D$4,0) -> 0 | ... AA30: =IF($Q30=TRUE,P30*$D$4,0) -> 0
B31: km² 3D | C31: 3D Tomography iteration (incl. Tomo PreSDM), UP TO 5 ITERATIONS | D31: 200-500 km² | F31: FALSE | G31: 250 | H31: 245 | I31: 230 | J31: 263 | K31: 198 | L31: 45 | M31: 94 | N31: 306.54 | O31: 295 | P31: 257 | Q31: =AND($D$4>=200,$D$4<500,F31=TRUE) -> FALSE | R31: =IF($Q31=TRUE,G31*$D$4,0) -> 0 | S31: =IF($Q31=TRUE,H31*$D$4,0) -> 0 | T31: =IF($Q31=TRUE,I31*$D$4,0) -> 0 | U31: =IF($Q31=TRUE,J31*$D$4,0) -> 0 | V31: =IF($Q31=TRUE,K31*$D$4,0) -> 0 | W31: =IF($Q31=TRUE,L31*$D$4,0) -> 0 | X31: =IF($Q31=TRUE,M31*$D$4,0) -> 0 | Y31: =IF($Q31=TRUE,N31*$D$4,0) -> 0 | ... AA31: =IF($Q31=TRUE,P31*$D$4,0) -> 0
B32: km² 3D | C32: 3D Tomography iteration (incl. Tomo PreSDM), UP TO 5 ITERATIONS | D32: >500 km² | F32: FALSE | G32: 200 | H32: 235 | I32: 220 | J32: 238 | K32: 179 | L32: 40 | M32: 81.5 | N32: 306.54 | O32: 285 | P32: 237 | Q32: =AND($D$4>=500,F32=TRUE) -> FALSE | R32: =IF($Q32=TRUE,G32*$D$4,0) -> 0 | S32: =IF($Q32=TRUE,H32*$D$4,0) -> 0 | T32: =IF($Q32=TRUE,I32*$D$4,0) -> 0 | U32: =IF($Q32=TRUE,J32*$D$4,0) -> 0 | V32: =IF($Q32=TRUE,K32*$D$4,0) -> 0 | W32: =IF($Q32=TRUE,L32*$D$4,0) -> 0 | X32: =IF($Q32=TRUE,M32*$D$4,0) -> 0 | Y32: =IF($Q32=TRUE,N32*$D$4,0) -> 0 | ... AA32: =IF($Q32=TRUE,P32*$D$4,0) -> 0
B33: km 2D | C33: 2D Additional Tomography iteration (incl. Tomo PreSDM for iteration) | D33: <200 km | F33: TRUE | G33: 25 | H33: 10.5 | I33: 50 | J33: 48 | K33: 20 | L33: 25 | M33: 6.5 | N33: 73.8 | O33: 60 | P33: 35 | Q33: =AND($D$2>0,$D$2<200,F33=TRUE) -> TRUE | R33: =IF($Q33=TRUE,G33*$D$2*($D$5-5),0) -> 3125 | S33: =IF($Q33=TRUE,H33*$D$2*($D$5-5),0) -> 1312.5 | T33: =IF($Q33=TRUE,I33*$D$2*($D$5-5),0) -> 6250 | U33: =IF($Q33=TRUE,J33*$D$2*($D$5-5),0) -> 6000 | V33: =IF($Q33=TRUE,K33*$D$2*($D$5-5),0) -> 2500 | W33: =IF($Q33=TRUE,L33*$D$2*($D$5-5),0) -> 3125 | X33: =IF($Q33=TRUE,M33*$D$2*($D$5-5),0) -> 812.5 | Y33: =IF($Q33=TRUE,N33*$D$2*($D$5-5),0) -> 9225 | ... AA33: =IF($Q33=TRUE,P33*$D$2*($D$5-5),0) -> 4375
B34: km 2D | C34: 2D Additional Tomography iteration (incl. Tomo PreSDM for iteration) | D34: 200-600 km | F34: FALSE | G34: 25 | H34: 10 | I34: 40 | J34: 45 | K34: 20 | L34: 20 | M34: 6 | N34: 73.8 | O34: 55 | P34: 35 | Q34: =AND($D$2>=200,$D$2<600,F34=TRUE) -> FALSE | R34: =IF($Q34=TRUE,G34*$D$2*($D$5-5),0) -> 0 | S34: =IF($Q34=TRUE,H34*$D$2*($D$5-5),0) -> 0 | T34: =IF($Q34=TRUE,I34*$D$2*($D$5-5),0) -> 0 | U34: =IF($Q34=TRUE,J34*$D$2*($D$5-5),0) -> 0 | V34: =IF($Q34=TRUE,K34*$D$2*($D$5-5),0) -> 0 | W34: =IF($Q34=TRUE,L34*$D$2*($D$5-5),0) -> 0 | X34: =IF($Q34=TRUE,M34*$D$2*($D$5-5),0) -> 0 | Y34: =IF($Q34=TRUE,N34*$D$2*($D$5-5),0) -> 0 | ... AA34: =IF($Q34=TRUE,P34*$D$2*($D$5-5),0) -> 0
B35: km 2D | C35: 2D Additional Tomography iteration (incl. Tomo PreSDM for iteration) | D35: >600 km | F35: FALSE | G35: 25 | H35: 9 | I35: 35 | J35: 38 | K35: 20 | L35: 20 | M35: 5 | N35: 73.8 | O35: 50 | P35: 35 | Q35: =AND($D$2>=600,F35=TRUE) -> FALSE | R35: =IF($Q35=TRUE,G35*$D$2*($D$5-5),0) -> 0 | S35: =IF($Q35=TRUE,H35*$D$2*($D$5-5),0) -> 0 | T35: =IF($Q35=TRUE,I35*$D$2*($D$5-5),0) -> 0 | U35: =IF($Q35=TRUE,J35*$D$2*($D$5-5),0) -> 0 | V35: =IF($Q35=TRUE,K35*$D$2*($D$5-5),0) -> 0 | W35: =IF($Q35=TRUE,L35*$D$2*($D$5-5),0) -> 0 | X35: =IF($Q35=TRUE,M35*$D$2*($D$5-5),0) -> 0 | Y35: =IF($Q35=TRUE,N35*$D$2*($D$5-5),0) -> 0 | ... AA35: =IF($Q35=TRUE,P35*$D$2*($D$5-5),0) -> 0
B36: km² 3D | C36: 3D Additional Tomography iteration (incl. Tomo PreSDM for iteration) | D36: 0-200 km² | F36: FALSE | G36: 60 | H36: 26 | I36: 65 | J36: 74 | K36: 20 | L36: 20 | M36: 18.5 | N36: 102.18 | O36: 60 | P36: 55 | Q36: =AND($D$4>0,$D$4<200,F36=TRUE) -> FALSE | R36: =IF($Q36=TRUE,G36*$D$4*($D$6-5),0) -> 0 | S36: =IF($Q36=TRUE,H36*$D$4*($D$6-5),0) -> 0 | T36: =IF($Q36=TRUE,I36*$D$4*($D$6-5),0) -> 0 | U36: =IF($Q36=TRUE,J36*$D$4*($D$6-5),0) -> 0 | V36: =IF($Q36=TRUE,K36*$D$4*($D$6-5),0) -> 0 | W36: =IF($Q36=TRUE,L36*$D$4*($D$6-5),0) -> 0 | X36: =IF($Q36=TRUE,M36*$D$4*($D$6-5),0) -> 0 | Y36: =IF($Q36=TRUE,N36*$D$4*($D$6-5),0) -> 0 | ... AA36: =IF($Q36=TRUE,P36*$D$4*($D$6-5),0) -> 0
B37: km² 3D | C37: 3D Additional Tomography iteration (incl. Tomo PreSDM for iteration) | D37: 200-500 km² | F37: FALSE | G37: 50 | H37: 25 | I37: 60 | J37: 71 | K37: 20 | L37: 20 | M37: 16 | N37: 102.18 | O37: 55 | P37: 51 | Q37: =AND($D$4>=200,$D$4<500,F37=TRUE) -> FALSE | R37: =IF($Q37=TRUE,G37*$D$4*($D$6-5),0) -> 0 | S37: =IF($Q37=TRUE,H37*$D$4*($D$6-5),0) -> 0 | T37: =IF($Q37=TRUE,I37*$D$4*($D$6-5),0) -> 0 | U37: =IF($Q37=TRUE,J37*$D$4*($D$6-5),0) -> 0 | V37: =IF($Q37=TRUE,K37*$D$4*($D$6-5),0) -> 0 | W37: =IF($Q37=TRUE,L37*$D$4*($D$6-5),0) -> 0 | X37: =IF($Q37=TRUE,M37*$D$4*($D$6-5),0) -> 0 | Y37: =IF($Q37=TRUE,N37*$D$4*($D$6-5),0) -> 0 | ... AA37: =IF($Q37=TRUE,P37*$D$4*($D$6-5),0) -> 0
B38: km² 3D | C38: 3D Additional Tomography iteration (incl. Tomo PreSDM for iteration) | D38: >500 km² | F38: FALSE | G38: 40 | H38: 23.5 | I38: 55 | J38: 69 | K38: 18 | L38: 20 | M38: 13.5 | N38: 102.18 | O38: 50 | P38: 47 | Q38: =AND($D$4>=500,F38=TRUE) -> FALSE | R38: =IF($Q38=TRUE,G38*$D$4*($D$6-5),0) -> 0 | S38: =IF($Q38=TRUE,H38*$D$4*($D$6-5),0) -> 0 | T38: =IF($Q38=TRUE,I38*$D$4*($D$6-5),0) -> 0 | U38: =IF($Q38=TRUE,J38*$D$4*($D$6-5),0) -> 0 | V38: =IF($Q38=TRUE,K38*$D$4*($D$6-5),0) -> 0 | W38: =IF($Q38=TRUE,L38*$D$4*($D$6-5),0) -> 0 | X38: =IF($Q38=TRUE,M38*$D$4*($D$6-5),0) -> 0 | Y38: =IF($Q38=TRUE,N38*$D$4*($D$6-5),0) -> 0 | ... AA38: =IF($Q38=TRUE,P38*$D$4*($D$6-5),0) -> 0
B39: km 2D | C39: 2D Pre-stack Depth Migration (PreSDM) | D39: <200 km | F39: TRUE | G39: 75 | H39: 47 | I39: 95 | J39: 56 | K39: 94.28 | L39: 50 | M39: 62 | N39: 51.23 | O39: 105 | P39: 97 | Q39: =AND($D$2>0,$D$2<200,F39=TRUE) -> TRUE | R39: =IF($Q39=TRUE,G39*$D$2,0) -> 9375 | S39: =IF($Q39=TRUE,H39*$D$2,0) -> 5875 | T39: =IF($Q39=TRUE,I39*$D$2,0) -> 11875 | U39: =IF($Q39=TRUE,J39*$D$2,0) -> 7000 | V39: =IF($Q39=TRUE,K39*$D$2,0) -> 11785 | W39: =IF($Q39=TRUE,L39*$D$2,0) -> 6250 | X39: =IF($Q39=TRUE,M39*$D$2,0) -> 7750 | Y39: =IF($Q39=TRUE,N39*$D$2,0) -> 6403.75 | ... AA39: =IF($Q39=TRUE,P39*$D$2,0) -> 12125
B40: km 2D | C40: 2D Pre-stack Depth Migration (PreSDM) | D40: 200-600 km | F40: FALSE | G40: 75 | H40: 45 | I40: 90 | J40: 54 | K40: 94.28 | L40: 40 | M40: 53 | N40: 51.23 | O40: 100 | P40: 87 | Q40: =AND($D$2>=200,$D$2<600,F40=TRUE) -> FALSE | R40: =IF($Q40=TRUE,G40*$D$2,0) -> 0 | S40: =IF($Q40=TRUE,H40*$D$2,0) -> 0 | T40: =IF($Q40=TRUE,I40*$D$2,0) -> 0 | U40: =IF($Q40=TRUE,J40*$D$2,0) -> 0 | V40: =IF($Q40=TRUE,K40*$D$2,0) -> 0 | W40: =IF($Q40=TRUE,L40*$D$2,0) -> 0 | X40: =IF($Q40=TRUE,M40*$D$2,0) -> 0 | Y40: =IF($Q40=TRUE,N40*$D$2,0) -> 0 | ... AA40: =IF($Q40=TRUE,P40*$D$2,0) -> 0
...

Sheet Tecnologías avanzadas
C1: Tamaño del proyecto 2D (km) | D1: 0 | AE1: TRUE
C2: Tamaño del proyecto 3D (km²) | D2: 174.8 | AE2: FALSE
C3: Número de tomografías 2D | D3: 0
C4: Número de tomografías 3D | D4: 5
G5: Absolute | H5: AGT | I5: EGS | J5: GT | K5: Geotomo | L5: Inforpetrol | M5: Petroseis | N5: Schlumberger | O5: Tecc | P5: Z-Terra | R5: Absolute | S5: AGT | T5: EGS | U5: GT | V5: Geotomo | W5: Inforpetrol | X5: Petroseis | Y5: Schlumberger | Z5: Tecc | AA5: Z-Terra
B6: UNIDAD | C6: DESCRIPCION AMPLIADA DEL SERVICIO | D6: Project Size | F6: Aplica | G6: VR UNIT USD $ | H6: VR UNIT USD $ | I6: VR UNIT USD $ | J6: VR UNIT USD $ | K6: VR UNIT USD $ | L6: VR UNIT USD $ | M6: VR UNIT USD $ | N6: VR UNIT USD $ | O6: VR UNIT USD $ | P6: VR UNIT USD $ | Q6: Aplica 2 | R6: Costo por servicio | S6: Costo por servicio | T6: Costo por servicio | U6: Costo por servicio | V6: Costo por servicio | W6: Costo por servicio | X6: Costo por servicio | Y6: Costo por servicio | Z6: Costo por servicio | AA6: Costo por servicio
A7: Time-domain preprocessing | B7: km 2D | C7: 5D Hybrid Trace Interpolation (5D HI) | F7: FALSE | J7: 30 | Q7: =AND($D$1>0,F7=TRUE) -> FALSE | R7: =IF($Q7=TRUE,G7*$D$1,0) -> 0 | S7: =IF($Q7=TRUE,H7*$D$1,0) -> 0 | T7: =IF($Q7=TRUE,I7*$D$1,0) -> 0 | U7: =IF($Q7=TRUE,J7*$D$1,0) -> 0 | V7: =IF($Q7=TRUE,K7*$D$1,0) -> 0 | W7: =IF($Q7=TRUE,L7*$D$1,0) -> 0 | X7: =IF($Q7=TRUE,M7*$D$1,0) -> 0 | Y7: =IF($Q7=TRUE,N7*$D$1,0) -> 0 | ... AA7: =IF($Q7=TRUE,P7*$D$1,0) -> 0
B8: km² 3D | C8: 5D Hybrid Trace Interpolation (5D HI) | F8: FALSE | J8: 41 | Q8: =AND($D$2>0,F8=TRUE) -> FALSE | R8: =IF($Q8=TRUE,G8*$D$2,0) -> 0 | S8: =IF($Q8=TRUE,H8*$D$2,0) -> 0 | T8: =IF($Q8=TRUE,I8*$D$2,0) -> 0 | U8: =IF($Q8=TRUE,J8*$D$2,0) -> 0 | V8: =IF($Q8=TRUE,K8*$D$2,0) -> 0 | W8: =IF($Q8=TRUE,L8*$D$2,0) -> 0 | X8: =IF($Q8=TRUE,M8*$D$2,0) -> 0 | Y8: =IF($Q8=TRUE,N8*$D$2,0) -> 0 | ... AA8: =IF($Q8=TRUE,P8*$D$2,0) -> 0
B9: km 2D | C9: Interpolation 5D | F9: FALSE | Q9: =AND($D$1>0,F9=TRUE) -> FALSE | R9: =IF($Q9=TRUE,G9*$D$1,0) -> 0 | S9: =IF($Q9=TRUE,H9*$D$1,0) -> 0 | T9: =IF($Q9=TRUE,I9*$D$1,0) -> 0 | U9: =IF($Q9=TRUE,J9*$D$1,0) -> 0 | V9: =IF($Q9=TRUE,K9*$D$1,0) -> 0 | W9: =IF($Q9=TRUE,L9*$D$1,0) -> 0 | X9: =IF($Q9=TRUE,M9*$D$1,0) -> 0 | Y9: =IF($Q9=TRUE,N9*$D$1,0) -> 0 | ... AA9: =IF($Q9=TRUE,P9*$D$1,0) -> 0
B10: km² 3D | C10: Interpolation 5D | F10: FALSE | L10: 10 | Q10: =AND($D$2>0,F10=TRUE) -> FALSE | R10: =IF($Q10=TRUE,G10*$D$2,0) -> 0 | S10: =IF($Q10=TRUE,H10*$D$2,0) -> 0 | T10: =IF($Q10=TRUE,I10*$D$2,0) -> 0 | U10: =IF($Q10=TRUE,J10*$D$2,0) -> 0 | V10: =IF($Q10=TRUE,K10*$D$2,0) -> 0 | W10: =IF($Q10=TRUE,L10*$D$2,0) -> 0 | X10: =IF($Q10=TRUE,M10*$D$2,0) -> 0 | Y10: =IF($Q10=TRUE,N10*$D$2,0) -> 0 | ... AA10: =IF($Q10=TRUE,P10*$D$2,0) -> 0
B11: km 2D | C11: 6D Interpolation | F11: FALSE | P11: 20 | Q11: =AND($D$1>0,F11=TRUE) -> FALSE | R11: =IF($Q11=TRUE,G11*$D$1,0) -> 0 | S11: =IF($Q11=TRUE,H11*$D$1,0) -> 0 | T11: =IF($Q11=TRUE,I11*$D$1,0) -> 0 | U11: =IF($Q11=TRUE,J11*$D$1,0) -> 0 | V11: =IF($Q11=TRUE,K11*$D$1,0) -> 0 | W11: =IF($Q11=TRUE,L11*$D$1,0) -> 0 | X11: =IF($Q11=TRUE,M11*$D$1,0) -> 0 | Y11: =IF($Q11=TRUE,N11*$D$1,0) -> 0 | ... AA11: =IF($Q11=TRUE,P11*$D$1,0) -> 0
B12: km² 3D | C12: 6D Interpolation | F12: FALSE | P12: 22 | Q12: =AND($D$2>0,F12=TRUE) -> FALSE | R12: =IF($Q12=TRUE,G12*$D$2,0) -> 0 | S12: =IF($Q12=TRUE,H12*$D$2,0) -> 0 | T12: =IF($Q12=TRUE,I12*$D$2,0) -> 0 | U12: =IF($Q12=TRUE,J12*$D$2,0) -> 0 | V12: =IF($Q12=TRUE,K12*$D$2,0) -> 0 | W12: =IF($Q12=TRUE,L12*$D$2,0) -> 0 | X12: =IF($Q12=TRUE,M12*$D$2,0) -> 0 | Y12: =IF($Q12=TRUE,N12*$D$2,0) -> 0 | ... AA12: =IF($Q12=TRUE,P12*$D$2,0) -> 0
B13: km 2D | C13: ML Deblending | F13: FALSE | H13: 15 | Q13: =AND($D$1>0,F13=TRUE) -> FALSE | R13: =IF($Q13=TRUE,G13*$D$1,0) -> 0 | S13: =IF($Q13=TRUE,H13*$D$1,0) -> 0 | T13: =IF($Q13=TRUE,I13*$D$1,0) -> 0 | U13: =IF($Q13=TRUE,J13*$D$1,0) -> 0 | V13: =IF($Q13=TRUE,K13*$D$1,0) -> 0 | W13: =IF($Q13=TRUE,L13*$D$1,0) -> 0 | X13: =IF($Q13=TRUE,M13*$D$1,0) -> 0 | Y13: =IF($Q13=TRUE,N13*$D$1,0) -> 0 | ... AA13: =IF($Q13=TRUE,P13*$D$1,0) -> 0
B14: km² 3D | C14: ML Deblending | F14: FALSE | H14: 30 | Q14: =AND($D$2>0,F14=TRUE) -> FALSE | R14: =IF($Q14=TRUE,G14*$D$2,0) -> 0 | S14: =IF($Q14=TRUE,H14*$D$2,0) -> 0 | T14: =IF($Q14=TRUE,I14*$D$2,0) -> 0 | U14: =IF($Q14=TRUE,J14*$D$2,0) -> 0 | V14: =IF($Q14=TRUE,K14*$D$2,0) -> 0 | W14: =IF($Q14=TRUE,L14*$D$2,0) -> 0 | X14: =IF($Q14=TRUE,M14*$D$2,0) -> 0 | Y14: =IF($Q14=TRUE,N14*$D$2,0) -> 0 | ... AA14: =IF($Q14=TRUE,P14*$D$2,0) -> 0
B15: km 2D | C15: Bandwidtg Extension - post stack | F15: FALSE | H15: 30 | Q15: =AND($D$1>0,F15=TRUE) -> FALSE | R15: =IF($Q15=TRUE,G15*$D$1,0) -> 0 | S15: =IF($Q15=TRUE,H15*$D$1,0) -> 0 | T15: =IF($Q15=TRUE,I15*$D$1,0) -> 0 | U15: =IF($Q15=TRUE,J15*$D$1,0) -> 0 | V15: =IF($Q15=TRUE,K15*$D$1,0) -> 0 | W15: =IF($Q15=TRUE,L15*$D$1,0) -> 0 | X15: =IF($Q15=TRUE,M15*$D$1,0) -> 0 | Y15: =IF($Q15=TRUE,N15*$D$1,0) -> 0 | ... AA15: =IF($Q15=TRUE,P15*$D$1,0) -> 0
B16: km² 3D | C16: Bandwidtg Extension - post stack | F16: FALSE | H16: 75 | Q16: =AND($D$2>0,F16=TRUE) -> FALSE | R16: =IF($Q16=TRUE,G16*$D$2,0) -> 0 | S16: =IF($Q16=TRUE,H16*$D$2,0) -> 0 | T16: =IF($Q16=TRUE,I16*$D$2,0) -> 0 | U16: =IF($Q16=TRUE,J16*$D$2,0) -> 0 | V16: =IF($Q16=TRUE,K16*$D$2,0) -> 0 | W16: =IF($Q16=TRUE,L16*$D$2,0) -> 0 | X16: =IF($Q16=TRUE,M16*$D$2,0) -> 0 | Y16: =IF($Q16=TRUE,N16*$D$2,0) -> 0 | ... AA16: =IF($Q16=TRUE,P16*$D$2,0) -> 0
B17: km 2D | C17: Bandwidtg Extension - pre stack | F17: FALSE | H17: 45 | Q17: =AND($D$1>0,F17=TRUE) -> FALSE | R17: =IF($Q17=TRUE,G17*$D$1,0) -> 0 | S17: =IF($Q17=TRUE,H17*$D$1,0) -> 0 | T17: =IF($Q17=TRUE,I17*$D$1,0) -> 0 | U17: =IF($Q17=TRUE,J17*$D$1,0) -> 0 | V17: =IF($Q17=TRUE,K17*$D$1,0) -> 0 | W17: =IF($Q17=TRUE,L17*$D$1,0) -> 0 | X17: =IF($Q17=TRUE,M17*$D$1,0) -> 0 | Y17: =IF($Q17=TRUE,N17*$D$1,0) -> 0 | ... AA17: =IF($Q17=TRUE,P17*$D$1,0) -> 0
B18: km² 3D | C18: Bandwidtg Extension - pre stack | F18: FALSE | H18: 100 | Q18: =AND($D$2>0,F18=TRUE) -> FALSE | R18: =IF($Q18=TRUE,G18*$D$2,0) -> 0 | S18: =IF($Q18=TRUE,H18*$D$2,0) -> 0 | T18: =IF($Q18=TRUE,I18*$D$2,0) -> 0 | U18: =IF($Q18=TRUE,J18*$D$2,0) -> 0 | V18: =IF($Q18=TRUE,K18*$D$2,0) -> 0 | W18: =IF($Q18=TRUE,L18*$D$2,0) -> 0 | X18: =IF($Q18=TRUE,M18*$D$2,0) -> 0 | Y18: =IF($Q18=TRUE,N18*$D$2,0) -> 0 | ... AA18: =IF($Q18=TRUE,P18*$D$2,0) -> 0
B19: km 2D | C19: Interactive Wavelet Shaping (IWS) | F19: FALSE | J19: 19 | Q19: =AND($D$1>0,F19=TRUE) -> FALSE | R19: =IF($Q19=TRUE,G19*$D$1,0) -> 0 | S19: =IF($Q19=TRUE,H19*$D$1,0) -> 0 | T19: =IF($Q19=TRUE,I19*$D$1,0) -> 0 | U19: =IF($Q19=TRUE,J19*$D$1,0) -> 0 | V19: =IF($Q19=TRUE,K19*$D$1,0) -> 0 | W19: =IF($Q19=TRUE,L19*$D$1,0) -> 0 | X19: =IF($Q19=TRUE,M19*$D$1,0) -> 0 | Y19: =IF($Q19=TRUE,N19*$D$1,0) -> 0 | ... AA19: =IF($Q19=TRUE,P19*$D$1,0) -> 0
B20: km² 3D | C20: Interactive Wavelet Shaping (IWS) | F20: FALSE | J20: 25 | Q20: =AND($D$2>0,F20=TRUE) -> FALSE | R20: =IF($Q20=TRUE,G20*$D$2,0) -> 0 | S20: =IF($Q20=TRUE,H20*$D$2,0) -> 0 | T20: =IF($Q20=TRUE,I20*$D$2,0) -> 0 | U20: =IF($Q20=TRUE,J20*$D$2,0) -> 0 | V20: =IF($Q20=TRUE,K20*$D$2,0) -> 0 | W20: =IF($Q20=TRUE,L20*$D$2,0) -> 0 | X20: =IF($Q20=TRUE,M20*$D$2,0) -> 0 | Y20: =IF($Q20=TRUE,N20*$D$2,0) -> 0 | ... AA20: =IF($Q20=TRUE,P20*$D$2,0) -> 0
B21: km 2D | C21: Ground Force Corrections (GFC) | F21: FALSE | J21: 18 | Q21: =AND($D$1>0,F21=TRUE) -> FALSE | R21: =IF($Q21=TRUE,G21*$D$1,0) -> 0 | S21: =IF($Q21=TRUE,H21*$D$1,0) -> 0 | T21: =IF($Q21=TRUE,I21*$D$1,0) -> 0 | U21: =IF($Q21=TRUE,J21*$D$1,0) -> 0 | V21: =IF($Q21=TRUE,K21*$D$1,0) -> 0 | W21: =IF($Q21=TRUE,L21*$D$1,0) -> 0 | X21: =IF($Q21=TRUE,M21*$D$1,0) -> 0 | Y21: =IF($Q21=TRUE,N21*$D$1,0) -> 0 | ... AA21: =IF($Q21=TRUE,P21*$D$1,0) -> 0
B22: km² 3D | C22: Ground Force Corrections (GFC) | F22: FALSE | J22: 24 | Q22: =AND($D$2>0,F22=TRUE) -> FALSE | R22: =IF($Q22=TRUE,G22*$D$2,0) -> 0 | S22: =IF($Q22=TRUE,H22*$D$2,0) -> 0 | T22: =IF($Q22=TRUE,I22*$D$2,0) -> 0 | U22: =IF($Q22=TRUE,J22*$D$2,0) -> 0 | V22: =IF($Q22=TRUE,K22*$D$2,0) -> 0 | W22: =IF($Q22=TRUE,L22*$D$2,0) -> 0 | X22: =IF($Q22=TRUE,M22*$D$2,0) -> 0 | Y22: =IF($Q22=TRUE,N22*$D$2,0) -> 0 | ... AA22: =IF($Q22=TRUE,P22*$D$2,0) -> 0
B23: km 2D | C23: Advance attenuation of Multiple Reflections - Techniques Tailored to Geology (AMR) | F23: FALSE | J23: 28 | Q23: =AND($D$1>0,F23=TRUE) -> FALSE | R23: =IF($Q23=TRUE,G23*$D$1,0) -> 0 | S23: =IF($Q23=TRUE,H23*$D$1,0) -> 0 | T23: =IF($Q23=TRUE,I23*$D$1,0) -> 0 | U23: =IF($Q23=TRUE,J23*$D$1,0) -> 0 | V23: =IF($Q23=TRUE,K23*$D$1,0) -> 0 | W23: =IF($Q23=TRUE,L23*$D$1,0) -> 0 | X23: =IF($Q23=TRUE,M23*$D$1,0) -> 0 | Y23: =IF($Q23=TRUE,N23*$D$1,0) -> 0 | ... AA23: =IF($Q23=TRUE,P23*$D$1,0) -> 0
B24: km² 3D | C24: Advance attenuation of Multiple Reflections - Techniques Tailored to Geology (AMR) | F24: FALSE | J24: 43 | Q24: =AND($D$2>0,F24=TRUE) -> FALSE | R24: =IF($Q24=TRUE,G24*$D$2,0) -> 0 | S24: =IF($Q24=TRUE,H24*$D$2,0) -> 0 | T24: =IF($Q24=TRUE,I24*$D$2,0) -> 0 | U24: =IF($Q24=TRUE,J24*$D$2,0) -> 0 | V24: =IF($Q24=TRUE,K24*$D$2,0) -> 0 | W24: =IF($Q24=TRUE,L24*$D$2,0) -> 0 | X24: =IF($Q24=TRUE,M24*$D$2,0) -> 0 | Y24: =IF($Q24=TRUE,N24*$D$2,0) -> 0 | ... AA24: =IF($Q24=TRUE,P24*$D$2,0) -> 0
B25: km 2D | C25: Enhance Coherency Processing (ECP - Pre-Stack) | F25: FALSE | J25: 28 | Q25: =AND($D$1>0,F25=TRUE) -> FALSE | R25: =IF($Q25=TRUE,G25*$D$1,0) -> 0 | S25: =IF($Q25=TRUE,H25*$D$1,0) -> 0 | T25: =IF($Q25=TRUE,I25*$D$1,0) -> 0 | U25: =IF($Q25=TRUE,J25*$D$1,0) -> 0 | V25: =IF($Q25=TRUE,K25*$D$1,0) -> 0 | W25: =IF($Q25=TRUE,L25*$D$1,0) -> 0 | X25: =IF($Q25=TRUE,M25*$D$1,0) -> 0 | Y25: =IF($Q25=TRUE,N25*$D$1,0) -> 0 | ... AA25: =IF($Q25=TRUE,P25*$D$1,0) -> 0
B26: km² 3D | C26: Enhance Coherency Processing (ECP - Pre-Stack) | F26: FALSE | J26: 43 | Q26: =AND($D$2>0,F26=TRUE) -> FALSE | R26: =IF($Q26=TRUE,G26*$D$2,0) -> 0 | S26: =IF($Q26=TRUE,H26*$D$2,0) -> 0 | T26: =IF($Q26=TRUE,I26*$D$2,0) -> 0 | U26: =IF($Q26=TRUE,J26*$D$2,0) -> 0 | V26: =IF($Q26=TRUE,K26*$D$2,0) -> 0 | W26: =IF($Q26=TRUE,L26*$D$2,0) -> 0 | X26: =IF($Q26=TRUE,M26*$D$2,0) -> 0 | Y26: =IF($Q26=TRUE,N26*$D$2,0) -> 0 | ... AA26: =IF($Q26=TRUE,P26*$D$2,0) -> 0
B27: km 2D | C27: Non-invasive removal of noise from seismic recording (NINEL) | F27: FALSE | J27: 15 | Q27: =AND($D$1>0,F27=TRUE) -> FALSE | R27: =IF($Q27=TRUE,G27*$D$1,0) -> 0 | S27: =IF($Q27=TRUE,H27*$D$1,0) -> 0 | T27: =IF($Q27=TRUE,I27*$D$1,0) -> 0 | U27: =IF($Q27=TRUE,J27*$D$1,0) -> 0 | V27: =IF($Q27=TRUE,K27*$D$1,0) -> 0 | W27: =IF($Q27=TRUE,L27*$D$1,0) -> 0 | X27: =IF($Q27=TRUE,M27*$D$1,0) -> 0 | Y27: =IF($Q27=TRUE,N27*$D$1,0) -> 0 | ... AA27: =IF($Q27=TRUE,P27*$D$1,0) -> 0
B28: km² 3D | C28: Non-invasive removal of noise from seismic recording (NINEL) | F28: FALSE | J28: 35 | Q28: =AND($D$2>0,F28=TRUE) -> FALSE | R28: =IF($Q28=TRUE,G28*$D$2,0) -> 0 | S28: =IF($Q28=TRUE,H28*$D$2,0) -> 0 | T28: =IF($Q28=TRUE,I28*$D$2,0) -> 0 | U28: =IF($Q28=TRUE,J28*$D$2,0) -> 0 | V28: =IF($Q28=TRUE,K28*$D$2,0) -> 0 | W28: =IF($Q28=TRUE,L28*$D$2,0) -> 0 | X28: =IF($Q28=TRUE,M28*$D$2,0) -> 0 | Y28: =IF($Q28=TRUE,N28*$D$2,0) -> 0 | ... AA28: =IF($Q28=TRUE,P28*$D$2,0) -> 0
B29: km 2D | C29: High Velocity Corrections (HVC) | F29: FALSE | J29: 29 | Q29: =AND($D$1>0,F29=TRUE) -> FALSE | R29: =IF($Q29=TRUE,G29*$D$1,0) -> 0 | S29: =IF($Q29=TRUE,H29*$D$1,0) -> 0 | T29: =IF($Q29=TRUE,I29*$D$1,0) -> 0 | U29: =IF($Q29=TRUE,J29*$D$1,0) -> 0 | V29: =IF($Q29=TRUE,K29*$D$1,0) -> 0 | W29: =IF($Q29=TRUE,L29*$D$1,0) -> 0 | X29: =IF($Q29=TRUE,M29*$D$1,0) -> 0 | Y29: =IF($Q29=TRUE,N29*$D$1,0) -> 0 | ... AA29: =IF($Q29=TRUE,P29*$D$1,0) -> 0
B30: km² 3D | C30: High Velocity Corrections (HVC) | F30: FALSE | J30: 50 | Q30: =AND($D$2>0,F30=TRUE) -> FALSE | R30: =IF($Q30=TRUE,G30*$D$2,0) -> 0 | S30: =IF($Q30=TRUE,H30*$D$2,0) -> 0 | T30: =IF($Q30=TRUE,I30*$D$2,0) -> 0 | U30: =IF($Q30=TRUE,J30*$D$2,0) -> 0 | V30: =IF($Q30=TRUE,K30*$D$2,0) -> 0 | W30: =IF($Q30=TRUE,L30*$D$2,0) -> 0 | X30: =IF($Q30=TRUE,M30*$D$2,0) -> 0 | Y30: =IF($Q30=TRUE,N30*$D$2,0) -> 0 | ... AA30: =IF($Q30=TRUE,P30*$D$2,0) -> 0
B31: km 2D | C31: Advanced Statics - static corrections in chalenging cases (Adv Statics) | F31: FALSE | J31: 29 | Q31: =AND($D$1>0,F31=TRUE) -> FALSE | R31: =IF($Q31=TRUE,G31*$D$1,0) -> 0 | S31: =IF($Q31=TRUE,H31*$D$1,0) -> 0 | T31: =IF($Q31=TRUE,I31*$D$1,0) -> 0 | U31: =IF($Q31=TRUE,J31*$D$1,0) -> 0 | V31: =IF($Q31=TRUE,K31*$D$1,0) -> 0 | W31: =IF($Q31=TRUE,L31*$D$1,0) -> 0 | X31: =IF($Q31=TRUE,M31*$D$1,0) -> 0 | Y31: =IF($Q31=TRUE,N31*$D$1,0) -> 0 | ... AA31: =IF($Q31=TRUE,P31*$D$1,0) -> 0
B32: km² 3D | C32: Advanced Statics - static corrections in chalenging cases (Adv Statics) | F32: FALSE | J32: 50 | Q32: =AND($D$2>0,F32=TRUE) -> FALSE | R32: =IF($Q32=TRUE,G32*$D$2,0) -> 0 | S32: =IF($Q32=TRUE,H32*$D$2,0) -> 0 | T32: =IF($Q32=TRUE,I32*$D$2,0) -> 0 | U32: =IF($Q32=TRUE,J32*$D$2,0) -> 0 | V32: =IF($Q32=TRUE,K32*$D$2,0) -> 0 | W32: =IF($Q32=TRUE,L32*$D$2,0) -> 0 | X32: =IF($Q32=TRUE,M32*$D$2,0) -> 0 | Y32: =IF($Q32=TRUE,N32*$D$2,0) -> 0 | ... AA32: =IF($Q32=TRUE,P32*$D$2,0) -> 0
B33: km 2D | C33: Modelling for Statics Corrections - Modeling low veloccity Layer (MLVL) | F33: FALSE | J33: 23 | Q33: =AND($D$1>0,F33=TRUE) -> FALSE | R33: =IF($Q33=TRUE,G33*$D$1,0) -> 0 | S33: =IF($Q33=TRUE,H33*$D$1,0) -> 0 | T33: =IF($Q33=TRUE,I33*$D$1,0) -> 0 | U33: =IF($Q33=TRUE,J33*$D$1,0) -> 0 | V33: =IF($Q33=TRUE,K33*$D$1,0) -> 0 | W33: =IF($Q33=TRUE,L33*$D$1,0) -> 0 | X33: =IF($Q33=TRUE,M33*$D$1,0) -> 0 | Y33: =IF($Q33=TRUE,N33*$D$1,0) -> 0 | ... AA33: =IF($Q33=TRUE,P33*$D$1,0) -> 0
B34: km² 3D | C34: Modelling for Statics Corrections - Modeling low veloccity Layer (MLVL) | F34: FALSE | J34: 50 | Q34: =AND($D$2>0,F34=TRUE) -> FALSE | R34: =IF($Q34=TRUE,G34*$D$2,0) -> 0 | S34: =IF($Q34=TRUE,H34*$D$2,0) -> 0 | T34: =IF($Q34=TRUE,I34*$D$2,0) -> 0 | U34: =IF($Q34=TRUE,J34*$D$2,0) -> 0 | V34: =IF($Q34=TRUE,K34*$D$2,0) -> 0 | W34: =IF($Q34=TRUE,L34*$D$2,0) -> 0 | X34: =IF($Q34=TRUE,M34*$D$2,0) -> 0 | Y34: =IF($Q34=TRUE,N34*$D$2,0) -> 0 | ... AA34: =IF($Q34=TRUE,P34*$D$2,0) -> 0
B35: km 2D | C35: Interactive Residual Static Corrections (IRSC) | F35: FALSE | J35: 24 | Q35: =AND($D$1>0,F35=TRUE) -> FALSE | R35: =IF($Q35=TRUE,G35*$D$1,0) -> 0 | S35: =IF($Q35=TRUE,H35*$D$1,0) -> 0 | T35: =IF($Q35=TRUE,I35*$D$1,0) -> 0 | U35: =IF($Q35=TRUE,J35*$D$1,0) -> 0 | V35: =IF($Q35=TRUE,K35*$D$1,0) -> 0 | W35: =IF($Q35=TRUE,L35*$D$1,0) -> 0 | X35: =IF($Q35=TRUE,M35*$D$1,0) -> 0 | Y35: =IF($Q35=TRUE,N35*$D$1,0) -> 0 | ... AA35: =IF($Q35=TRUE,P35*$D$1,0) -> 0
B36: km² 3D | C36: Interactive Residual Static Corrections (IRSC) | F36: FALSE | J36: 36 | Q36: =AND($D$2>0,F36=TRUE) -> FALSE | R36: =IF($Q36=TRUE,G36*$D$2,0) -> 0 | S36: =IF($Q36=TRUE,H36*$D$2,0) -> 0 | T36: =IF($Q36=TRUE,I36*$D$2,0) -> 0 | U36: =IF($Q36=TRUE,J36*$D$2,0) -> 0 | V36: =IF($Q36=TRUE,K36*$D$2,0) -> 0 | W36: =IF($Q36=TRUE,L36*$D$2,0) -> 0 | X36: =IF($Q36=TRUE,M36*$D$2,0) -> 0 | Y36: =IF($Q36=TRUE,N36*$D$2,0) -> 0 | ... AA36: =IF($Q36=TRUE,P36*$D$2,0) -> 0
B37: km 2D | C37: Linear Noise Elimination by Hybrid Modeling (Hybrid Noise Elimination) | F37: FALSE | J37: 15 | Q37: =AND($D$1>0,F37=TRUE) -> FALSE | R37: =IF($Q37=TRUE,G37*$D$1,0) -> 0 | S37: =IF($Q37=TRUE,H37*$D$1,0) -> 0 | T37: =IF($Q37=TRUE,I37*$D$1,0) -> 0 | U37: =IF($Q37=TRUE,J37*$D$1,0) -> 0 | V37: =IF($Q37=TRUE,K37*$D$1,0) -> 0 | W37: =IF($Q37=TRUE,L37*$D$1,0) -> 0 | X37: =IF($Q37=TRUE,M37*$D$1,0) -> 0 | Y37: =IF($Q37=TRUE,N37*$D$1,0) -> 0 | ... AA37: =IF($Q37=TRUE,P37*$D$1,0) -> 0
B38: km² 3D | C38: Linear Noise Elimination by Hybrid Modeling (Hybrid Noise Elimination) | F38: FALSE | J38: 35 | Q38: =AND($D$2>0,F38=TRUE) -> FALSE | R38: =IF($Q38=TRUE,G38*$D$2,0) -> 0 | S38: =IF($Q38=TRUE,H38*$D$2,0) -> 0 | T38: =IF($Q38=TRUE,I38*$D$2,0) -> 0 | U38: =IF($Q38=TRUE,J38*$D$2,0) -> 0 | V38: =IF($Q38=TRUE,K38*$D$2,0) -> 0 | W38: =IF($Q38=TRUE,L38*$D$2,0) -> 0 | X38: =IF($Q38=TRUE,M38*$D$2,0) -> 0 | Y38: =IF($Q38=TRUE,N38*$D$2,0) -> 0 | ... AA38: =IF($Q38=TRUE,P38*$D$2,0) -> 0
B39: km 2D | C39: Power line attenuation | F39: FALSE | Q39: =AND($D$1>0,F39=TRUE) -> FALSE | R39: =IF($Q39=TRUE,G39*$D$1,0) -> 0 | S39: =IF($Q39=TRUE,H39*$D$1,0) -> 0 | T39: =IF($Q39=TRUE,I39*$D$1,0) -> 0 | U39: =IF($Q39=TRUE,J39*$D$1,0) -> 0 | V39: =IF($Q39=TRUE,K39*$D$1,0) -> 0 | W39: =IF($Q39=TRUE,L39*$D$1,0) -> 0 | X39: =IF($Q39=TRUE,M39*$D$1,0) -> 0 | Y39: =IF($Q39=TRUE,N39*$D$1,0) -> 0 | ... AA39: =IF($Q39=TRUE,P39*$D$1,0) -> 0
B40: km² 3D | C40: Power line attenuation | F40: FALSE | K40: 144 | Q40: =AND($D$2>0,F40=TRUE) -> FALSE | R40: =IF($Q40=TRUE,G40*$D$2,0) -> 0 | S40: =IF($Q40=TRUE,H40*$D$2,0) -> 0 | T40: =IF($Q40=TRUE,I40*$D$2,0) -> 0 | U40: =IF($Q40=TRUE,J40*$D$2,0) -> 0 | V40: =IF($Q40=TRUE,K40*$D$2,0) -> 0 | W40: =IF($Q40=TRUE,L40*$D$2,0) -> 0 | X40: =IF($Q40=TRUE,M40*$D$2,0) -> 0 | Y40: =IF($Q40=TRUE,N40*$D$2,0) -> 0 | ... AA40: =IF($Q40=TRUE,P40*$D$2,0) -> 0
...

Sheet Absolute Imaging

Sheet AGT

Sheet EGS

Sheet Geofizyka Torum

Sheet Geotomo

Sheet Inforpetrol

Sheet Petroseis

Sheet Schlumberger

Sheet Teec Solutions

Sheet Z Terra
